---
title:  "비동기 테스트 코드 에러 해결"
date: 2024-03-07T13:20:42+09:00
categories: 
    - 프로그래밍
tags:
    - nodejs
    - 테스트 코드
---

로컬에서 테스트 코드를 실행했을 때 문제 없이 통과했지만 github actions를 이용해서 테스트를 할 때 실패를 하였다.

![](https://i.imgur.com/zShS7cs.png)

count가 변경되었다는 것에 주목하여 관련된 코드를 찾아보았더니 아래의 코드를 발견했다
```ts
// 1
it('queries a order by id', () => {
    expect(service.findOne(id)).resolves.toMatchObject({
      count: 1,
      userId: user.id,
      productId: product.id,
    })
// 2
it('updates a order', async () => {
  const res = await service.update(id, { count: 2 });
  expect(res.affected).toBe(1);
});
```

1번 테스트가 실행할 때 비동기 코드라서 blocking되지 않고 계속 코드를 실행한다. 2번 테스트 코드가 실행되고 count는 2로 변경된다. 비동기의 특징으로 순서를 보장할 수 없기 때문에 간헐적으로 테스트 코드가 실패를 하였다.

해결 방법으로 1번 코드도 async/await을 사용하여 비동기 작업의 순서를 보장하게 하였다
```ts
it('queries a order by id', async () => {
  const order = await service.findOne(id);
  expect(order).toMatchObject({
    count: 1,
    userId: user.id,
    productId: product.id,
  });
});
```

![](https://i.imgur.com/OMGgfV0.png)
